<?xml version="1.0" encoding="utf-8"?>
<!-- This URDF was automatically created by SolidWorks to URDF Exporter! Originally created by Stephen Brawner (brawner@gmail.com) 
     Commit Version: 1.6.0-1-g15f4949  Build Version: 1.6.7594.29634
     For more information, please see http://wiki.ros.org/sw_urdf_exporter -->
<robot
  name="robot_arm_urdf2">
  <link
    name="base_link">
    <inertial>
      <origin
        xyz="0.09493433727649 -0.24896941864695 0.138373636319561"
        rpy="0 0 0" />
      <mass
        value="3.29455147777089" />
      <inertia
        ixx="0.00995925241650689"
        ixy="3.16182443753372E-08"
        ixz="9.9292168917905E-05"
        iyy="0.00406952044203457"
        iyz="-3.32817700678746E-07"
        izz="0.0125352508721362" />
    </inertial>
    <visual>
      <origin
        xyz="0 0 0"
        rpy="0 0 0" />
      <geometry>
        <mesh
          filename="package://robot_arm_urdf2/meshes/base_link.STL" />
      </geometry>
      <material
        name="">
        <color
          rgba="0.752941176470588 0.752941176470588 0.752941176470588 1" />
      </material>
    </visual>
    <collision>
      <origin
        xyz="0 0 0"
        rpy="0 0 0" />
      <geometry>
        <mesh
          filename="package://robot_arm_urdf2/meshes/base_link.STL" />
      </geometry>
    </collision>
  </link>
  <link
    name="link_1">
    <inertial>
      <origin
        xyz="0.00262673512257354 -0.0104202948612931 0.061830634325769"
        rpy="0 0 0" />
      <mass
        value="1.16742314297254" />
      <inertia
        ixx="0.00169307454364985"
        ixy="1.32919034516992E-06"
        ixz="3.66310698862148E-07"
        iyy="0.00192382004725997"
        iyz="2.79792317621602E-06"
        izz="0.00174170652061311" />
    </inertial>
    <visual>
      <origin
        xyz="0 0 0"
        rpy="0 0 0" />
      <geometry>
        <mesh
          filename="package://robot_arm_urdf2/meshes/link_1.STL" />
      </geometry>
      <material
        name="">
        <color
          rgba="0.752941176470588 0.752941176470588 0.752941176470588 1" />
      </material>
    </visual>
    <collision>
      <origin
        xyz="0 0 0"
        rpy="0 0 0" />
      <geometry>
        <mesh
          filename="package://robot_arm_urdf2/meshes/link_1.STL" />
      </geometry>
    </collision>
  </link>
  <joint
    name="joint_1"
    type="continuous">
    <origin
      xyz="0.0746747981630567 -0.248918304083793 0.176725477929593"
      rpy="0 0 0" />
    <parent
      link="base_link" />
    <child
      link="link_1" />
    <axis
      xyz="0 0 1" />
  </joint>
  <link
    name="link_2">
    <inertial>
      <origin
        xyz="0.000417720178564271 0.15554107916594 -0.0157176447577974"
        rpy="0 0 0" />
      <mass
        value="1.75147052409867" />
      <inertia
        ixx="0.00790422703369088"
        ixy="9.2807084033169E-08"
        ixz="2.66766034264405E-07"
        iyy="0.00116003992203804"
        iyz="-1.63024013646404E-06"
        izz="0.00876600054911234" />
    </inertial>
    <visual>
      <origin
        xyz="0 0 0"
        rpy="0 0 0" />
      <geometry>
        <mesh
          filename="package://robot_arm_urdf2/meshes/link_2.STL" />
      </geometry>
      <material
        name="">
        <color
          rgba="0.752941176470588 0.752941176470588 0.752941176470588 1" />
      </material>
    </visual>
    <collision>
      <origin
        xyz="0 0 0"
        rpy="0 0 0" />
      <geometry>
        <mesh
          filename="package://robot_arm_urdf2/meshes/link_2.STL" />
      </geometry>
    </collision>
  </link>
  <joint
    name="joint_2"
    type="continuous">
    <origin
      xyz="0 0 0.1284"
      rpy="1.5707963267949 0 0" />
    <parent
      link="link_1" />
    <child
      link="link_2" />
    <axis
      xyz="0 0 1" />
  </joint>
  <link
    name="link_3">
    <inertial>
      <origin
        xyz="0.244750970387759 -0.00303524877196659 -0.022454915680964"
        rpy="0 0 0" />
      <mass
        value="1.03361204187583" />
      <inertia
        ixx="0.000423709109053549"
        ixy="-1.70759294027429E-07"
        ixz="-1.63025000337088E-06"
        iyy="0.00646801105394727"
        iyz="-2.6677408856283E-07"
        izz="0.00665322997436231" />
    </inertial>
    <visual>
      <origin
        xyz="0 0 0"
        rpy="0 0 0" />
      <geometry>
        <mesh
          filename="package://robot_arm_urdf2/meshes/link_3.STL" />
      </geometry>
      <material
        name="">
        <color
          rgba="0.752941176470588 0.752941176470588 0.752941176470588 1" />
      </material>
    </visual>
    <collision>
      <origin
        xyz="0 0 0"
        rpy="0 0 0" />
      <geometry>
        <mesh
          filename="package://robot_arm_urdf2/meshes/link_3.STL" />
      </geometry>
    </collision>
  </link>
  <joint
    name="joint_3"
    type="continuous">
    <origin
      xyz="0 0.41276532251213 -2.50000000016903E-05"
      rpy="0 0 0" />
    <parent
      link="link_2" />
    <child
      link="link_3" />
    <axis
      xyz="0 0 -1" />
    <limit
      lower="0"
      upper="0"
      effort="0"
      velocity="0" />
  </joint>
  <link
    name="link_4">
    <inertial>
      <origin
        xyz="0.0519930291501622 0.00236001343420333 0.0220008409503921"
        rpy="0 0 0" />
      <mass
        value="0.616548567520716" />
      <inertia
        ixx="0.000270262566895787"
        ixy="-7.3689845338962E-06"
        ixz="8.46887275929433E-07"
        iyy="0.000408670631214262"
        iyz="-5.18772851773383E-06"
        izz="0.000543924297412793" />
    </inertial>
    <visual>
      <origin
        xyz="0 0 0"
        rpy="0 0 0" />
      <geometry>
        <mesh
          filename="package://robot_arm_urdf2/meshes/link_4.STL" />
      </geometry>
      <material
        name="">
        <color
          rgba="0.752941176470588 0.752941176470588 0.752941176470588 1" />
      </material>
    </visual>
    <collision>
      <origin
        xyz="0 0 0"
        rpy="0 0 0" />
      <geometry>
        <mesh
          filename="package://robot_arm_urdf2/meshes/link_4.STL" />
      </geometry>
    </collision>
  </link>
  <joint
    name="joint_4"
    type="continuous">
    <origin
      xyz="0.406400000000002 0 0"
      rpy="0 0 0" />
    <parent
      link="link_3" />
    <child
      link="link_4" />
    <axis
      xyz="0 0 1" />
  </joint>
  <link
    name="link_5">
    <inertial>
      <origin
        xyz="-4.4674055565963E-09 -2.80779680755794E-07 -0.0143674040514952"
        rpy="0 0 0" />
      <mass
        value="0.0120448502222473" />
      <inertia
        ixx="2.92551229592988E-06"
        ixy="1.50032208362877E-10"
        ixz="-3.30441242627022E-12"
        iyy="2.92551180907455E-06"
        iyz="2.64439731174617E-12"
        izz="3.75709130125596E-07" />
    </inertial>
    <visual>
      <origin
        xyz="0 0 0"
        rpy="0 0 0" />
      <geometry>
        <mesh
          filename="package://robot_arm_urdf2/meshes/link_5.STL" />
      </geometry>
      <material
        name="">
        <color
          rgba="0.752941176470588 0.752941176470588 0.752941176470588 1" />
      </material>
    </visual>
    <collision>
      <origin
        xyz="0 0 0"
        rpy="0 0 0" />
      <geometry>
        <mesh
          filename="package://robot_arm_urdf2/meshes/link_5.STL" />
      </geometry>
    </collision>
  </link>
  <joint
    name="joint_5"
    type="continuous">
    <origin
      xyz="0.108599999999997 0.0130000000000096 0"
      rpy="-1.5707963267949 0 -1.5707963267949" />
    <parent
      link="link_4" />
    <child
      link="link_5" />
    <axis
      xyz="0 0 1" />
  </joint>
  <link
    name="tool">
    <inertial>
      <origin
        xyz="-6.27511828841243E-05 -6.63813688049075E-05 0.108521452509426"
        rpy="0 0 0" />
      <mass
        value="0.364411803488704" />
      <inertia
        ixx="0.000182829358285011"
        ixy="5.55969481525768E-08"
        ixz="1.0797858656776E-05"
        iyy="0.000149448231695818"
        iyz="-2.48956925261575E-07"
        izz="6.1623613994971E-05" />
    </inertial>
    <visual>
      <origin
        xyz="0 0 0"
        rpy="0 0 0" />
      <geometry>
        <mesh
          filename="package://robot_arm_urdf2/meshes/tool.STL" />
      </geometry>
      <material
        name="">
        <color
          rgba="0.752941176470588 0.752941176470588 0.752941176470588 1" />
      </material>
    </visual>
    <collision>
      <origin
        xyz="0 0 0"
        rpy="0 0 0" />
      <geometry>
        <mesh
          filename="package://robot_arm_urdf2/meshes/tool.STL" />
      </geometry>
    </collision>
  </link>
  <joint
    name="joint_6"
    type="fixed">
    <origin
      xyz="0 0 0.00240000000000007"
      rpy="0 0 0" />
    <parent
      link="link_5" />
    <child
      link="tool" />
    <axis
      xyz="0 0 0" />
  </joint>
</robot>